<?xml version="1.0" ?>
<robot name="differential_robot" xmlns:xacro="http://www.ros.org/wiki/xacro">

<xacro:include filename="$(find differential_robot_description)/urdf/materials.xacro" />
<xacro:include filename="$(find differential_robot_description)/urdf/differential_robot.trans" />
<xacro:include filename="$(find differential_robot_description)/urdf/differential_robot.gazebo" />
<link name="base_link">
  <inertial>
    <origin xyz="-0.00022908232525586226 2.3580301423313124e-17 0.03576360775085303" rpy="0 0 0"/>
    <mass value="24.22202593851102"/>
    <inertia ixx="0.085012" iyy="0.183018" izz="0.257123" ixy="0.0" iyz="0.0" ixz="-4e-06"/>
  </inertial>
  <visual>
    <origin xyz="0 0 0" rpy="0 0 0"/>
    <geometry>
      <mesh filename="file://$(find differential_robot_description)/meshes/base_link.stl" scale="0.001 0.001 0.001"/>
    </geometry>
    <material name="silver"/>
  </visual>
  <collision>
    <origin xyz="0 0 0" rpy="0 0 0"/>
    <geometry>
      <mesh filename="file://$(find differential_robot_description)/meshes/base_link.stl" scale="0.001 0.001 0.001"/>
    </geometry>
  </collision>
</link>

<link name="Lidar_1">
  <inertial>
    <origin xyz="-5.790023100122029e-18 5.790023100122029e-18 0.012499999999999997" rpy="0 0 0"/>
    <mass value="1.541343895667492"/>
    <inertia ixx="0.001044" iyy="0.001044" izz="0.001927" ixy="-0.0" iyz="0.0" ixz="-0.0"/>
  </inertial>
  <visual>
    <origin xyz="-0.0 -0.0 -0.07" rpy="0 0 0"/>
    <geometry>
      <mesh filename="file://$(find differential_robot_description)/meshes/Lidar_1.stl" scale="0.001 0.001 0.001"/>
    </geometry>
    <material name="silver"/>
  </visual>
  <collision>
    <origin xyz="-0.0 -0.0 -0.07" rpy="0 0 0"/>
    <geometry>
      <mesh filename="file://$(find differential_robot_description)/meshes/Lidar_1.stl" scale="0.001 0.001 0.001"/>
    </geometry>
  </collision>
</link>

<link name="caster_wheel_1">
  <inertial>
    <origin xyz="0.08999999999999997 -1.1795831361170316e-17 -0.0037098385304082365" rpy="0 0 0"/>
    <mass value="0.0591073268273161"/>
    <inertia ixx="5e-06" iyy="5e-06" izz="9e-06" ixy="0.0" iyz="0.0" ixz="0.0"/>
  </inertial>
  <visual>
    <origin xyz="-0.0 -0.0 -0.01" rpy="0 0 0"/>
    <geometry>
      <mesh filename="file://$(find differential_robot_description)/meshes/caster_wheel_1.stl" scale="0.001 0.001 0.001"/>
    </geometry>
    <material name="silver"/>
  </visual>
  <collision>
    <origin xyz="-0.0 -0.0 -0.01" rpy="0 0 0"/>
    <geometry>
      <mesh filename="file://$(find differential_robot_description)/meshes/caster_wheel_1.stl" scale="0.001 0.001 0.001"/>
    </geometry>
  </collision>
</link>

<link name="right_wheel_1">
  <inertial>
    <origin xyz="0.0 -0.015000000000000013 -1.3877787807814457e-17" rpy="0 0 0"/>
    <mass value="0.9063102106524855"/>
    <inertia ixx="0.000346" iyy="0.000555" izz="0.000346" ixy="0.0" iyz="-0.0" ixz="-0.0"/>
  </inertial>
  <visual>
    <origin xyz="0.1 0.12 -0.035" rpy="0 0 0"/>
    <geometry>
      <mesh filename="file://$(find differential_robot_description)/meshes/right_wheel_1.stl" scale="0.001 0.001 0.001"/>
    </geometry>
    <material name="silver"/>
  </visual>
  <collision>
    <origin xyz="0.1 0.12 -0.035" rpy="0 0 0"/>
    <geometry>
      <mesh filename="file://$(find differential_robot_description)/meshes/right_wheel_1.stl" scale="0.001 0.001 0.001"/>
    </geometry>
  </collision>
</link>

<link name="left_wheel_1">
  <inertial>
    <origin xyz="0.0 0.015000000000000013 -1.3877787807814457e-17" rpy="0 0 0"/>
    <mass value="0.9063102106524855"/>
    <inertia ixx="0.000346" iyy="0.000555" izz="0.000346" ixy="-0.0" iyz="0.0" ixz="-0.0"/>
  </inertial>
  <visual>
    <origin xyz="0.1 -0.12 -0.035" rpy="0 0 0"/>
    <geometry>
      <mesh filename="file://$(find differential_robot_description)/meshes/left_wheel_1.stl" scale="0.001 0.001 0.001"/>
    </geometry>
    <material name="silver"/>
  </visual>
  <collision>
    <origin xyz="0.1 -0.12 -0.035" rpy="0 0 0"/>
    <geometry>
      <mesh filename="file://$(find differential_robot_description)/meshes/left_wheel_1.stl" scale="0.001 0.001 0.001"/>
    </geometry>
  </collision>
</link>

<link name="camera">
  <inertial>
    <origin xyz="-0.010000000000000092 4.519363186134586e-18 0.0040000000000000036" rpy="0 0 0"/>
    <mass value="0.006279999999999998"/>
    <inertia ixx="0.0" iyy="0.0" izz="0.0" ixy="-0.0" iyz="-0.0" ixz="0.0"/>
  </inertial>
  <visual>
    <origin xyz="-0.15 -0.0 -0.06" rpy="0 0 0"/>
    <geometry>
      <mesh filename="file://$(find differential_robot_description)/meshes/camera_1.stl" scale="0.001 0.001 0.001"/>
    </geometry>
    <material name="silver"/>
  </visual>
  <collision>
    <origin xyz="-0.15 -0.0 -0.06" rpy="0 0 0"/>
    <geometry>
      <mesh filename="file://$(find differential_robot_description)/meshes/camera_1.stl" scale="0.001 0.001 0.001"/>
    </geometry>
  </collision>
</link>

<joint name="lidar_joint" type="fixed">
  <origin xyz="0.0 0.0 0.07" rpy="0 0 0"/>
  <parent link="base_link"/>
  <child link="Lidar_1"/>
</joint>

<joint name="caster_joint" type="fixed">
  <origin xyz="0.0 0.0 0.01" rpy="0 0 0"/>
  <parent link="base_link"/>
  <child link="caster_wheel_1"/>
</joint>

<joint name="rightwheel_joint" type="continuous">
  <origin xyz="-0.1 -0.12 0.035" rpy="0 0 0"/>
  <parent link="base_link"/>
  <child link="right_wheel_1"/>
  <axis xyz="0.0 1.0 0.0"/>
</joint>

<joint name="leftwheel_joint" type="continuous">
  <origin xyz="-0.1 0.12 0.035" rpy="0 0 0"/>
  <parent link="base_link"/>
  <child link="left_wheel_1"/>
  <axis xyz="0.0 1.0 0.0"/>
</joint>

<joint name="camera_joint" type="fixed">
  <origin xyz="0.15 0.0 0.06" rpy="0 0 0"/>
  <parent link="base_link"/>
  <child link="camera"/>
</joint>

</robot>
