<?xml version="1.0" ?>
<robot name="mobile_robot" xmlns:xacro="http://www.ros.org/wiki/xacro">

<xacro:include filename="$(find mobile_robot_description)/urdf/materials.xacro" />
<xacro:include filename="$(find mobile_robot_description)/urdf/mobile_robot.trans" />
<xacro:include filename="$(find mobile_robot_description)/urdf/mobile_robot.gazebo" />
<link name="base_link">
  <inertial>
    <origin xyz="-0.002715560508885082 -9.745129932985736e-18 0.05094989391420786" rpy="0 0 0"/>
    <mass value="14.652515580631277"/>
    <inertia ixx="0.020781" iyy="0.114226" izz="0.12794" ixy="-0.0" iyz="-0.0" ixz="0.001258"/>
  </inertial>
  <visual>
    <origin xyz="0 0 0" rpy="0 0 0"/>
    <geometry>
      <mesh filename="file://$(find mobile_robot_description)/meshes/base_link.stl" scale="0.001 0.001 0.001"/>
    </geometry>
    <material name="silver"/>
  </visual>
  <collision>
    <origin xyz="0 0 0" rpy="0 0 0"/>
    <geometry>
      <mesh filename="file://$(find mobile_robot_description)/meshes/base_link.stl" scale="0.001 0.001 0.001"/>
    </geometry>
  </collision>
</link>

<link name="lidar_1">
  <inertial>
    <origin xyz="0.0 -5.0260617188559274e-18 0.004999999999999977" rpy="0 0 0"/>
    <mass value="0.22195352097611887"/>
    <inertia ixx="5.2e-05" iyy="5.2e-05" izz="0.0001" ixy="-0.0" iyz="0.0" ixz="0.0"/>
  </inertial>
  <visual>
    <origin xyz="0.09 -0.0 -0.095" rpy="0 0 0"/>
    <geometry>
      <mesh filename="file://$(find mobile_robot_description)/meshes/lidar_1.stl" scale="0.001 0.001 0.001"/>
    </geometry>
    <material name="silver"/>
  </visual>
  <collision>
    <origin xyz="0.09 -0.0 -0.095" rpy="0 0 0"/>
    <geometry>
      <mesh filename="file://$(find mobile_robot_description)/meshes/lidar_1.stl" scale="0.001 0.001 0.001"/>
    </geometry>
  </collision>
</link>

<link name="camera_1">
  <inertial>
    <origin xyz="0.014999999999999986 0.0 0.0050000000000000044" rpy="0 0 0"/>
    <mass value="0.0157"/>
    <inertia ixx="1e-06" iyy="0.0" izz="1e-06" ixy="0.0" iyz="0.0" ixz="0.0"/>
  </inertial>
  <visual>
    <origin xyz="0.15 -0.0 -0.075" rpy="0 0 0"/>
    <geometry>
      <mesh filename="file://$(find mobile_robot_description)/meshes/camera_1.stl" scale="0.001 0.001 0.001"/>
    </geometry>
    <material name="silver"/>
  </visual>
  <collision>
    <origin xyz="0.15 -0.0 -0.075" rpy="0 0 0"/>
    <geometry>
      <mesh filename="file://$(find mobile_robot_description)/meshes/camera_1.stl" scale="0.001 0.001 0.001"/>
    </geometry>
  </collision>
</link>

<link name="left_wheel_1">
  <inertial>
    <origin xyz="0.0 -0.010000000000000009 -6.938893903907228e-18" rpy="0 0 0"/>
    <mass value="0.789168074581756"/>
    <inertia ixx="0.000342" iyy="0.000631" izz="0.000342" ixy="0.0" iyz="-0.0" ixz="0.0"/>
  </inertial>
  <visual>
    <origin xyz="-0.115 0.075 -0.04" rpy="0 0 0"/>
    <geometry>
      <mesh filename="file://$(find mobile_robot_description)/meshes/left_wheel_1.stl" scale="0.001 0.001 0.001"/>
    </geometry>
    <material name="silver"/>
  </visual>
  <collision>
    <origin xyz="-0.115 0.075 -0.04" rpy="0 0 0"/>
    <geometry>
      <mesh filename="file://$(find mobile_robot_description)/meshes/left_wheel_1.stl" scale="0.001 0.001 0.001"/>
    </geometry>
  </collision>
</link>

<link name="right_wheel_1">
  <inertial>
    <origin xyz="0.0 0.010000000000000009 -6.938893903907228e-18" rpy="0 0 0"/>
    <mass value="0.789168074581756"/>
    <inertia ixx="0.000342" iyy="0.000631" izz="0.000342" ixy="0.0" iyz="0.0" ixz="0.0"/>
  </inertial>
  <visual>
    <origin xyz="-0.115 -0.075 -0.04" rpy="0 0 0"/>
    <geometry>
      <mesh filename="file://$(find mobile_robot_description)/meshes/right_wheel_1.stl" scale="0.001 0.001 0.001"/>
    </geometry>
    <material name="silver"/>
  </visual>
  <collision>
    <origin xyz="-0.115 -0.075 -0.04" rpy="0 0 0"/>
    <geometry>
      <mesh filename="file://$(find mobile_robot_description)/meshes/right_wheel_1.stl" scale="0.001 0.001 0.001"/>
    </geometry>
  </collision>
</link>

<link name="caster_wheel_1">
  <inertial>
    <origin xyz="0.0 2.120369787642346e-18 -0.003749999999999999" rpy="0 0 0"/>
    <mass value="0.016441001553786576"/>
    <inertia ixx="0.0" iyy="0.0" izz="1e-06" ixy="0.0" iyz="0.0" ixz="-0.0"/>
  </inertial>
  <visual>
    <origin xyz="0.125 -0.0 -0.01" rpy="0 0 0"/>
    <geometry>
      <mesh filename="file://$(find mobile_robot_description)/meshes/caster_wheel_1.stl" scale="0.001 0.001 0.001"/>
    </geometry>
    <material name="silver"/>
  </visual>
  <collision>
    <origin xyz="0.125 -0.0 -0.01" rpy="0 0 0"/>
    <geometry>
      <mesh filename="file://$(find mobile_robot_description)/meshes/caster_wheel_1.stl" scale="0.001 0.001 0.001"/>
    </geometry>
  </collision>
</link>

<joint name="lidar_joint" type="fixed">
  <origin xyz="-0.09 0.0 0.095" rpy="0 0 0"/>
  <parent link="base_link"/>
  <child link="lidar_1"/>
</joint>

<joint name="camera_joint" type="fixed">
  <origin xyz="-0.15 0.0 0.075" rpy="0 0 0"/>
  <parent link="base_link"/>
  <child link="camera_1"/>
</joint>

<joint name="left_wheel_joint" type="continuous">
  <origin xyz="0.115 -0.075 0.04" rpy="0 0 0"/>
  <parent link="base_link"/>
  <child link="left_wheel_1"/>
  <axis xyz="0.0 -1.0 0.0"/>
</joint>

<joint name="right_wheel_joint" type="continuous">
  <origin xyz="0.115 0.075 0.04" rpy="0 0 0"/>
  <parent link="base_link"/>
  <child link="right_wheel_1"/>
  <axis xyz="0.0 1.0 0.0"/>
</joint>

<joint name="caster_wheel_joint" type="fixed">
  <origin xyz="-0.125 0.0 0.01" rpy="0 0 0"/>
  <parent link="base_link"/>
  <child link="caster_wheel_1"/>
</joint>

</robot>
